<?xml version="1.0" encoding="utf-8"?>
<!-- This URDF was automatically created by SolidWorks to URDF Exporter! Originally created by Stephen Brawner (brawner@gmail.com) 
     Commit Version: 1.6.0-1-g15f4949  Build Version: 1.6.7594.29634
     For more information, please see http://wiki.ros.org/sw_urdf_exporter -->
<robot name="cr5_robot">
  <link name="dummy_link" />
  <link name="base_link">
    <inertial>
      <origin xyz="-8.0961E-06 0.0019103 0.028995" rpy="0 0 0" />
      <mass value="0.90882" />
      <inertia
        ixx="0.0014545"
        ixy="4.2968E-08"
        ixz="-1.8199E-07"
        iyy="0.001345"
        iyz="-6.243E-06"
        izz="0.002155" />
    </inertial>
    <visual>
      <origin xyz="0 0 0" rpy="0 0 0" />
      <geometry>
        <mesh filename="package://dobot_description/meshes/cr5/base_link.dae" />
      </geometry>
      <material
        name="">
        <color rgba="0 0 0 1" />
      </material>
    </visual>
    <collision>
      <origin xyz="0 0 0" rpy="0 0 0" />
      <geometry>
        <mesh filename="package://dobot_description/meshes/cr5/base_link.dae" />
      </geometry>
    </collision>
  </link>

  <joint name="dummy_joint" type="fixed">
    <parent link="dummy_link" />
    <child  link="base_link" />
  </joint>


  <link  name="Link1">
    <inertial>
      <origin xyz="-8.7268E-07 -0.0032576 -0.0076748" rpy="0 0 0" />
      <mass value="1.6123" />
      <inertia
        ixx="0.0029122"
        ixy="5.7387E-09"
        ixz="1.9945E-08"
        iyy="0.0028191"
        iyz="0.00044094"
        izz="0.0032836" />
    </inertial>
    <visual>
      <origin xyz="0 0 0" rpy="0 0 0" />
      <geometry>
        <mesh filename="package://dobot_description/meshes/cr5/Link1.dae" />
      </geometry>
      <material
        name="">
        <color rgba="1 1 1 1" />
      </material>
    </visual>
    <collision>
      <origin xyz="0 0 0" rpy="0 0 0" />
      <geometry>
        <mesh filename="package://dobot_description/meshes/cr5/Link1.dae" />
      </geometry>
    </collision>
  </link>

  <joint name="joint1" type="revolute">
    <origin xyz="0 0 0.147" rpy="0 0 0" />
    <parent link="base_link" />
    <child link="Link1" />
    <axis xyz="0 0 1" />
    <limit lower="-3.14" upper="3.14" effort="0" velocity="0" />
  </joint>

  <link name="Link2">
    <inertial>
      <origin xyz="-0.21351 -1.3842E-06 0.14252" rpy="0 0 0" />
      <mass value="5.5186" />
      <inertia
        ixx="0.0085919"
        ixy="7.5552E-07"
        ixz="-7.8922E-07"
        iyy="0.027553"
        iyz="1.4629E-07"
        izz="0.028294" />
    </inertial>
    <visual>
      <origin xyz="0 0 0" rpy="0 0 0" />
      <geometry>
        <mesh filename="package://dobot_description/meshes/cr5/Link2.dae" />
      </geometry>
      <material
        name="">
        <color rgba="1 1 1 1" />
      </material>
    </visual>
    <collision>
      <origin xyz="0 0 0" rpy="0 0 0" />
      <geometry>
        <mesh filename="package://dobot_description/meshes/cr5/Link2.dae" />
      </geometry>
    </collision>
  </link>

  <joint name="joint2" type="revolute">
    <origin xyz="0 0 0" rpy="1.5708 1.5708 0" />
    <parent link="Link1" />
    <child  link="Link2" />
    <axis xyz="0 0 1" />
    <limit lower="-3.14" upper="3.14" effort="0" velocity="0" />
  </joint>

  <link name="Link3">
    <inertial>
      <origin xyz="-0.15231 -1.4079E-07 0.022693" rpy="0 0 0" />
      <mass value="2.8536" />
      <inertia
        ixx="0.0032608"
        ixy="-3.2147E-10"
        ixz="0.00012363"
        iyy="0.0092967"
        iyz="2.9478E-10"
        izz="0.0095552" />
    </inertial>
    <visual>
      <origin xyz="0 0 0" rpy="0 0 0" />
      <geometry>
        <mesh filename="package://dobot_description/meshes/cr5/Link3.dae" />
      </geometry>
      <material
        name="">
        <color rgba="1 1 1 1" />
      </material>
    </visual>
    <collision>
      <origin xyz="0 0 0"  rpy="0 0 0" />
      <geometry>
        <mesh filename="package://dobot_description/meshes/cr5/Link3.dae" />
      </geometry>
    </collision>
  </link>

  <joint name="joint3" type="revolute">
    <origin xyz="-0.427 0 0" rpy="0 0 0" />
    <parent link="Link2" />
    <child link="Link3" />
    <axis  xyz="0 0 1" />
    <limit lower="-3.14"  upper="3.14"  effort="0" velocity="0" />
  </joint>

  <link name="Link4">
    <inertial>
      <origin xyz="-3.2386E-07 -0.002077 -0.0015548" rpy="0 0 0" />
      <mass value="0.67058" />
      <inertia
        ixx="0.00066939"
        ixy="4.1975E-10"
        ixz="-1.0734E-08"
        iyy="0.00065424"
        iyz="0.00011081"
        izz="0.00065365" />
    </inertial>
    <visual>
      <origin xyz="0 0 0" rpy="0 0 0" />
      <geometry>
        <mesh filename="package://dobot_description/meshes/cr5/Link4.dae" />
      </geometry>
      <material name="">
        <color rgba="1 1 1 1" />
      </material>
    </visual>
    <collision>
      <origin xyz="0 0 0" rpy="0 0 0" />
      <geometry>
        <mesh filename="package://dobot_description/meshes/cr5/Link4.dae" />
      </geometry>
    </collision>
  </link>

  <joint name="joint4" type="revolute">
    <origin xyz="-0.357 0 0.141" rpy="0 0 -1.5708" />
    <parent link="Link3" />
    <child link="Link4" />
    <axis xyz="0 0 1" />
    <limit lower="-3.14" upper="3.14" effort="0" velocity="0" />
  </joint>
  <link
    name="Link5">
    <inertial>
      <origin xyz="-3.7738E-07 -0.0045777 -0.0012971" rpy="0 0 0" />
      <mass value="0.7269" />
      <inertia
        ixx="0.00073069"
        ixy="-5.7806E-09"
        ixz="6.7132E-09"
        iyy="0.00071195"
        iyz="-0.00011926"
        izz="0.00071391" />
    </inertial>
    <visual>
      <origin xyz="0 0 0" rpy="0 0 0" />
      <geometry>
        <mesh filename="package://dobot_description/meshes/cr5/Link5.dae" />
      </geometry>
      <material name="">
        <color rgba="1 1 1 1" />
      </material>
    </visual>
    <collision>
      <origin xyz="0 0 0" rpy="0 0 0" />
      <geometry>
        <mesh filename="package://dobot_description/meshes/cr5/Link5.dae" />
      </geometry>
    </collision>
  </link>

  <joint name="joint5" type="revolute">
    <origin xyz="0 -0.116 0" rpy="1.5708 0 0" />
    <parent link="Link4" />
    <child link="Link5" />
    <axis xyz="0 0 1" />
    <limit lower="-3.14" upper="3.14" effort="0" velocity="0" />
  </joint>

  <link name="Link6">
    <inertial>
      <origin xyz="5.0777E-11 9.3774E-05 -0.019285" rpy="0 0 0" />
      <mass value="0.15789" />
      <inertia
        ixx="7.8045E-05"
        ixy="6.1582E-15"
        ixz="6.2471E-14"
        iyy="7.9168E-05"
        iyz="-1.3822E-07"
        izz="0.00012951" />
    </inertial>
    <visual>
      <origin xyz="0 0 0" rpy="0 0 0" />
      <geometry>
        <mesh filename="package://dobot_description/meshes/cr5/Link6.dae" />
      </geometry>
      <material name="">
        <color rgba="1 1 1 1" />
      </material>
    </visual>
    <collision>
      <origin xyz="0 0 0" rpy="0 0 0" />
      <geometry>
        <mesh filename="package://dobot_description/meshes/cr5/Link6.dae" />
      </geometry>
    </collision>
  </link>

  <joint name="joint6" type="revolute">
    <origin xyz="0 0.105 0"  rpy="-1.5708 0 0" />
    <parent link="Link5" />
    <child link="Link6" />
    <axis xyz="0 0 1" />
    <limit lower="-3.14" upper="3.14" effort="0" velocity="0" />
  </joint>

  <!-- Robotiq 2F-85 Gripper -->
  <link name="robotiq_arg2f_base_link">
    <inertial>
      <origin rpy="0 0 0" xyz="8.625E-08 -4.6583E-06 0.03145"/>
      <mass value="0.22652"/>
      <inertia ixx="0.00020005" ixy="-4.2442E-10" ixz="-2.9069E-10" iyy="0.00017832" iyz="-3.4402E-08" izz="0.00013478"/>
    </inertial>
    <visual>
      <origin rpy="0 0 0" xyz="0 0 0"/>
      <geometry>
        <mesh filename="package://dobot_description/meshes/robotiq/visual/robotiq_arg2f_base_link.stl"/>
      </geometry>
      <material name="">
        <color rgba="0.1 0.1 0.1 1"/>
      </material>
    </visual>
    <collision>
      <origin rpy="0 0 0" xyz="0 0 0"/>
      <geometry>
        <mesh filename="package://dobot_description/meshes/robotiq/collision/robotiq_arg2f_base_link.stl"/>
      </geometry>
    </collision>
  </link>

  <!-- Gripper attachment joint -->
  <joint name="gripper_attachment_joint" type="fixed">
    <origin xyz="0 0 0" rpy="0 0 1.5708" />
    <parent link="Link6" />
    <child link="robotiq_arg2f_base_link" />
  </joint>

  <!-- Left outer knuckle -->
  <link name="left_outer_knuckle">
    <inertial>
      <origin rpy="0 0 0" xyz="-0.000200000000003065 0.0199435877845359 0.0292245259211331"/>
      <mass value="0.00853198276973456"/>
      <inertia ixx="2.89328108496468E-06" ixy="-1.57935047237397E-19" ixz="-1.93980378593255E-19" iyy="1.86719750325683E-06" iyz="-1.21858577871576E-06" izz="1.21905238907251E-06"/>
    </inertial>
    <visual>
      <origin rpy="0 0 0" xyz="0 0 0"/>
      <geometry>
        <mesh filename="package://dobot_description/meshes/robotiq/visual/robotiq_arg2f_85_outer_knuckle.dae" scale="0.001 0.001 0.001"/>
      </geometry>
      <material name="">
        <color rgba="0.792156862745098 0.819607843137255 0.933333333333333 1"/>
      </material>
    </visual>
    <collision>
      <origin rpy="0 0 0" xyz="0 0 0"/>
      <geometry>
        <mesh filename="package://dobot_description/meshes/robotiq/collision/robotiq_arg2f_85_outer_knuckle.dae" scale="0.001 0.001 0.001"/>
      </geometry>
    </collision>
  </link>

  <!-- Left outer finger -->
  <link name="left_outer_finger">
    <inertial>
      <origin rpy="0 0 0" xyz="0.00030115855001899 0.0373907951953854 -0.0208027427000385"/>
      <mass value="0.022614240507152"/>
      <inertia ixx="1.52518312458174E-05" ixy="9.76583423954399E-10" ixz="-5.43838577022588E-10" iyy="6.17694243867776E-06" iyz="6.78636130740228E-06" izz="1.16494917907219E-05"/>
    </inertial>
    <visual>
      <origin rpy="0 0 0" xyz="0 0 0"/>
      <geometry>
        <mesh filename="package://dobot_description/meshes/robotiq/visual/robotiq_arg2f_85_outer_finger.dae" scale="0.001 0.001 0.001"/>
      </geometry>
      <material name="">
        <color rgba="0.1 0.1 0.1 1"/>
      </material>
    </visual>
    <collision>
      <origin rpy="0 0 0" xyz="0 0 0"/>
      <geometry>
        <mesh filename="package://dobot_description/meshes/robotiq/collision/robotiq_arg2f_85_outer_finger.dae" scale="0.001 0.001 0.001"/>
      </geometry>
    </collision>
  </link>

  <!-- Left inner finger -->
  <link name="left_inner_finger">
    <inertial>
      <origin rpy="0 0 0" xyz="0.000299999999999317 0.0160078233491243 -0.0136945669206257"/>
      <mass value="0.0104003125914103"/>
      <inertia ixx="2.71909453810972E-06" ixy="1.35402465472579E-21" ixz="-7.1817349065269E-22" iyy="7.69100314106116E-07" iyz="6.74715432769696E-07" izz="2.30315190420171E-06"/>
    </inertial>
    <visual>
      <origin rpy="0 0 0" xyz="0 0 0"/>
      <geometry>
        <mesh filename="package://dobot_description/meshes/robotiq/visual/robotiq_arg2f_85_inner_finger.dae" scale="0.001 0.001 0.001"/>
      </geometry>
      <material name="">
        <color rgba="0.1 0.1 0.1 1"/>
      </material>
    </visual>
    <collision>
      <origin rpy="0 0 0" xyz="0 0 0"/>
      <geometry>
        <mesh filename="package://dobot_description/meshes/robotiq/collision/robotiq_arg2f_85_inner_finger.dae" scale="0.001 0.001 0.001"/>
      </geometry>
    </collision>
  </link>

  <!-- Left inner finger pad -->
  <link name="left_inner_finger_pad">
    <visual>
      <origin rpy="0 0 0" xyz="0 0 0"/>
      <geometry>
        <box size="0.022 0.00635 0.0375"/>
      </geometry>
      <material name="">
        <color rgba="0.9 0.9 0.9 1"/>
      </material>
    </visual>
    <collision>
      <origin rpy="0 0 0" xyz="0 0 0"/>
      <geometry>
        <box size="0.022 0.00635 0.0375"/>
      </geometry>
    </collision>
  </link>

  <!-- Left inner knuckle -->
  <link name="left_inner_knuckle">
    <inertial>
      <origin rpy="0 0 0" xyz="0.000123011831763771 0.0507850843201817 0.00103968640075166"/>
      <mass value="0.0271177346495152"/>
      <inertia ixx="2.61910379223783E-05" ixy="-2.43616858946494E-07" ixz="-6.37789906117123E-09" iyy="2.8270243746167E-06" iyz="-5.37200748039765E-07" izz="2.83695868220296E-05"/>
    </inertial>
    <visual>
      <origin rpy="0 0 0" xyz="0 0 0"/>
      <geometry>
        <mesh filename="package://dobot_description/meshes/robotiq/visual/robotiq_arg2f_85_inner_knuckle.dae" scale="0.001 0.001 0.001"/>
      </geometry>
      <material name="">
        <color rgba="0.1 0.1 0.1 1"/>
      </material>
    </visual>
    <collision>
      <origin rpy="0 0 0" xyz="0 0 0"/>
      <geometry>
        <mesh filename="package://dobot_description/meshes/robotiq/collision/robotiq_arg2f_85_inner_knuckle.dae" scale="0.001 0.001 0.001"/>
      </geometry>
    </collision>
  </link>

  <!-- Right outer knuckle -->
  <link name="right_outer_knuckle">
    <inertial>
      <origin rpy="0 0 0" xyz="-0.000200000000003065 -0.0199435877845359 0.0292245259211331"/>
      <mass value="0.00853198276973456"/>
      <inertia ixx="2.89328108496468E-06" ixy="1.57935047237397E-19" ixz="-1.93980378593255E-19" iyy="1.86719750325683E-06" iyz="1.21858577871576E-06" izz="1.21905238907251E-06"/>
    </inertial>
    <visual>
      <origin rpy="0 0 0" xyz="0 0 0"/>
      <geometry>
        <mesh filename="package://dobot_description/meshes/robotiq/visual/robotiq_arg2f_85_outer_knuckle.dae" scale="0.001 0.001 0.001"/>
      </geometry>
      <material name="">
        <color rgba="0.792156862745098 0.819607843137255 0.933333333333333 1"/>
      </material>
    </visual>
    <collision>
      <origin rpy="0 0 0" xyz="0 0 0"/>
      <geometry>
        <mesh filename="package://dobot_description/meshes/robotiq/collision/robotiq_arg2f_85_outer_knuckle.dae" scale="0.001 0.001 0.001"/>
      </geometry>
    </collision>
  </link>

  <!-- Right outer finger -->
  <link name="right_outer_finger">
    <inertial>
      <origin rpy="0 0 0" xyz="0.00030115855001899 -0.0373907951953854 -0.0208027427000385"/>
      <mass value="0.022614240507152"/>
      <inertia ixx="1.52518312458174E-05" ixy="-9.76583423954399E-10" ixz="-5.43838577022588E-10" iyy="6.17694243867776E-06" iyz="-6.78636130740228E-06" izz="1.16494917907219E-05"/>
    </inertial>
    <visual>
      <origin rpy="0 0 0" xyz="0 0 0"/>
      <geometry>
        <mesh filename="package://dobot_description/meshes/robotiq/visual/robotiq_arg2f_85_outer_finger.dae" scale="0.001 0.001 0.001"/>
      </geometry>
      <material name="">
        <color rgba="0.1 0.1 0.1 1"/>
      </material>
    </visual>
    <collision>
      <origin rpy="0 0 0" xyz="0 0 0"/>
      <geometry>
        <mesh filename="package://dobot_description/meshes/robotiq/collision/robotiq_arg2f_85_outer_finger.dae" scale="0.001 0.001 0.001"/>
      </geometry>
    </collision>
  </link>

  <!-- Right inner finger -->
  <link name="right_inner_finger">
    <inertial>
      <origin rpy="0 0 0" xyz="0.000299999999999317 -0.0160078233491243 -0.0136945669206257"/>
      <mass value="0.0104003125914103"/>
      <inertia ixx="2.71909453810972E-06" ixy="-1.35402465472579E-21" ixz="-7.1817349065269E-22" iyy="7.69100314106116E-07" iyz="-6.74715432769696E-07" izz="2.30315190420171E-06"/>
    </inertial>
    <visual>
      <origin rpy="0 0 0" xyz="0 0 0"/>
      <geometry>
        <mesh filename="package://dobot_description/meshes/robotiq/visual/robotiq_arg2f_85_inner_finger.dae" scale="0.001 0.001 0.001"/>
      </geometry>
      <material name="">
        <color rgba="0.1 0.1 0.1 1"/>
      </material>
    </visual>
    <collision>
      <origin rpy="0 0 0" xyz="0 0 0"/>
      <geometry>
        <mesh filename="package://dobot_description/meshes/robotiq/collision/robotiq_arg2f_85_inner_finger.dae" scale="0.001 0.001 0.001"/>
      </geometry>
    </collision>
  </link>

  <!-- Right inner finger pad -->
  <link name="right_inner_finger_pad">
    <visual>
      <origin rpy="0 0 0" xyz="0 0 0"/>
      <geometry>
        <box size="0.022 0.00635 0.0375"/>
      </geometry>
      <material name="">
        <color rgba="0.9 0.9 0.9 1"/>
      </material>
    </visual>
    <collision>
      <origin rpy="0 0 0" xyz="0 0 0"/>
      <geometry>
        <box size="0.022 0.00635 0.0375"/>
      </geometry>
    </collision>
  </link>

  <!-- Right inner knuckle -->
  <link name="right_inner_knuckle">
    <inertial>
      <origin rpy="0 0 0" xyz="0.000123011831763771 -0.0507850843201817 0.00103968640075166"/>
      <mass value="0.0271177346495152"/>
      <inertia ixx="2.61910379223783E-05" ixy="2.43616858946494E-07" ixz="-6.37789906117123E-09" iyy="2.8270243746167E-06" iyz="5.37200748039765E-07" izz="2.83695868220296E-05"/>
    </inertial>
    <visual>
      <origin rpy="0 0 0" xyz="0 0 0"/>
      <geometry>
        <mesh filename="package://dobot_description/meshes/robotiq/visual/robotiq_arg2f_85_inner_knuckle.dae" scale="0.001 0.001 0.001"/>
      </geometry>
      <material name="">
        <color rgba="0.1 0.1 0.1 1"/>
      </material>
    </visual>
    <collision>
      <origin rpy="0 0 0" xyz="0 0 0"/>
      <geometry>
        <mesh filename="package://dobot_description/meshes/robotiq/collision/robotiq_arg2f_85_inner_knuckle.dae" scale="0.001 0.001 0.001"/>
      </geometry>
    </collision>
  </link>

  <!-- Joints for the gripper -->
  <!-- Left finger joint -->
  <joint name="finger_joint" type="revolute">
    <origin xyz="0 -0.0306011 0.054904" rpy="0 0 3.14159"/>
    <parent link="robotiq_arg2f_base_link"/>
    <child link="left_outer_knuckle"/>
    <axis xyz="1 0 0"/>
    <limit lower="0" upper="0.8" velocity="0.5" effort="1000"/>
  </joint>

  <!-- Left outer finger joint -->
  <joint name="left_outer_finger_joint" type="fixed">
    <origin xyz="0 0.0315 -0.0041" rpy="0 0 0"/>
    <parent link="left_outer_knuckle"/>
    <child link="left_outer_finger"/>
  </joint>

  <!-- Left inner finger joint -->
  <joint name="left_inner_finger_joint" type="revolute">
    <origin xyz="0 0.0061 0.0471" rpy="0 0 0"/>
    <parent link="left_outer_finger"/>
    <child link="left_inner_finger"/>
    <axis xyz="1 0 0"/>
    <limit lower="-0.8757" upper="0" velocity="0.5" effort="1000"/>
    <mimic joint="finger_joint" multiplier="-1" offset="0"/>
  </joint>

  <!-- Left inner finger pad joint -->
  <joint name="left_inner_finger_pad_joint" type="fixed">
    <origin xyz="0 -0.0220203 0.03242" rpy="0 0 0"/>
    <parent link="left_inner_finger"/>
    <child link="left_inner_finger_pad"/>
  </joint>

  <!-- Left inner knuckle joint -->
  <joint name="left_inner_knuckle_joint" type="revolute">
    <origin xyz="0 -0.0127 0.06142" rpy="0 0 3.141592653589793"/>
    <parent link="robotiq_arg2f_base_link"/>
    <child link="left_inner_knuckle"/>
    <axis xyz="1 0 0"/>
    <limit lower="0" upper="0.8757" velocity="0.5" effort="1000"/>
    <mimic joint="finger_joint" multiplier="1" offset="0"/>
  </joint>

  <!-- Right finger joint -->
  <joint name="right_finger_joint" type="revolute">
    <origin xyz="0 0.0306011 0.054904" rpy="0 0 0"/>
    <parent link="robotiq_arg2f_base_link"/>
    <child link="right_outer_knuckle"/>
    <axis xyz="1 0 0"/>
    <limit lower="0" upper="0.81" velocity="0.5" effort="1000"/>
    <mimic joint="finger_joint" multiplier="1" offset="0"/>
  </joint>

  <!-- Right outer finger joint -->
  <joint name="right_outer_finger_joint" type="fixed">
    <origin xyz="0 0.0315 -0.0041" rpy="0 0 0"/>
    <parent link="right_outer_knuckle"/>
    <child link="right_outer_finger"/>
  </joint>

  <!-- Right inner finger joint -->
  <joint name="right_inner_finger_joint" type="revolute">
    <origin xyz="0 0.0061 0.0471" rpy="0 0 0"/>
    <parent link="right_outer_finger"/>
    <child link="right_inner_finger"/>
    <axis xyz="1 0 0"/>
    <limit lower="-0.8757" upper="0" velocity="0.5" effort="1000"/>
    <mimic joint="finger_joint" multiplier="-1" offset="0"/>
  </joint>

  <!-- Right inner finger pad joint -->
  <joint name="right_inner_finger_pad_joint" type="fixed">
    <origin xyz="0 -0.0220203446692936 0.03242" rpy="0 0 0"/>
    <parent link="right_inner_finger"/>
    <child link="right_inner_finger_pad"/>
  </joint>

  <!-- Right inner knuckle joint -->
  <joint name="right_inner_knuckle_joint" type="revolute">
    <origin xyz="0 0.0127 0.06142" rpy="0 0 0.0"/>
    <parent link="robotiq_arg2f_base_link"/>
    <child link="right_inner_knuckle"/>
    <axis xyz="1 0 0"/>
    <limit lower="0" upper="0.8757" velocity="0.5" effort="1000"/>
    <mimic joint="finger_joint" multiplier="1" offset="0"/>
  </joint>

</robot>